Workbook
Name __xleta.FILTER: #NAME?
Name capeg: #REF!
Name capeg: #REF!
Name pkwtlap: #REF!
Name pkwtlap: #REF!

Sheet A
A2: JENIS KELAMIN
A3: NO | B3: JENIS KELAMIN | C3: JUMLAH
A4: 1 | B4: LAKI LAKI | C4: =COUNTIFS(Database!AB5:AB376,"laki-laki") -> 347
A5: 2 | B5: PEREMPUAN | C5: =COUNTIFS(Database!AB5:AB378,"Perempuan") -> 25
B6: TOTAL | C6: =SUM(C4:C5) -> 372
A9: Berdasarkan Jumlah Karyawan
A10: No | B10: Penempatan | C10: Golongan | G10: Jumlah
C11: Direksi | D11: Organik INKA | E11: IMSS Tetap | F11: PKWT
A12: 1 | B12: Kantor Salak | C12: =COUNTIFS(Database!$M$5:$M$376,"Direksi",Database!$U$5:$U$376,"IMSS") -> 0 | D12: =COUNTIFS(Database!$M$5:$M$376,"ORGANIK",Database!$U$5:$U$376,"IMSS") -> 0 | E12: =COUNTIFS(Database!$M$5:$M$376,"TETAP",Database!$U$5:$U$376,"IMSS") -> 0 | F12: =COUNTIFS(Database!$M$5:$M$376,"PKWT",Database!$U$5:$U$376,"IMSS") -> 31 | G12: =SUM(C12:F12) -> 31
A13: 2 | B13: GUDANG | C13: =COUNTIFS(Database!$M$5:$M$376,"Direksi",Database!$U$5:$U$376,"GUDANG") -> 0 | D13: =COUNTIFS(Database!$M$5:$M$376,"ORGANIK",Database!$U$5:$U$376,"GUDANG") -> 0 | E13: =COUNTIFS(Database!$M$5:$M$376,"TETAP",Database!$U$5:$U$376,"GUDANG") -> 0 | F13: =COUNTIFS(Database!$M$5:$M$376,"PKWT",Database!$U$5:$U$376,"GUDANG") -> 1 | G13: =SUM(C13:F13) -> 1
A14: 3 | B14: INKA | C14: =COUNTIFS(Database!$M$5:$M$376,"Direksi",Database!$U$5:$U$376,"INKA") -> 0 | D14: =COUNTIFS(Database!$M$5:$M$376,"ORGANIK",Database!$U$5:$U$376,"INKA") -> 0 | E14: =COUNTIFS(Database!$M$5:$M$376,"TETAP",Database!$U$5:$U$376,"INKA") -> 0 | F14: =COUNTIFS(Database!$M$5:$M$376,"PKWT",Database!$U$5:$U$376,"INKA") -> 58 | G14: =SUM(C14:F14) -> 58
A15: 4 | B15: MRO | C15: =COUNTIFS(Database!$M$5:$M$376,"Direksi",Database!$U$5:$U$376,"MRO") -> 0 | D15: =COUNTIFS(Database!$M$5:$M$376,"ORGANIK",Database!$U$5:$U$376,"MRO") -> 0 | E15: =COUNTIFS(Database!$M$5:$M$376,"TETAP",Database!$U$5:$U$376,"MRO") -> 0 | F15: =COUNTIFS(Database!$M$5:$M$376,"PKWT",Database!$U$5:$U$376,"MRO") -> 0 | G15: =SUM(C15:F15) -> 0
A16: 5 | B16: PMU | C16: =COUNTIFS(Database!$M$5:$M$376,"Direksi",Database!$U$5:$U$376,"PMU") -> 0 | D16: =COUNTIFS(Database!$M$5:$M$376,"ORGANIK",Database!$U$5:$U$376,"PMU") -> 0 | E16: =COUNTIFS(Database!$M$5:$M$376,"TETAP",Database!$U$5:$U$376,"PMU") -> 0 | F16: =COUNTIFS(Database!$M$5:$M$376,"PKWT",Database!$U$5:$U$376,"PMU") -> 0 | G16: =SUM(C16:F16) -> 0
A17: 6 | B17: Bandung | C17: =COUNTIFS(Database!$M$5:$M$376,"Direksi",Database!$U$5:$U$376,"BANDUNG") -> 0 | D17: =COUNTIFS(Database!$M$5:$M$376,"ORGANIK",Database!$U$5:$U$376,"BANDUNG") -> 0 | E17: =COUNTIFS(Database!$M$5:$M$376,"TETAP",Database!$U$5:$U$376,"BANDUNG") -> 0 | F17: =COUNTIFS(Database!$M$5:$M$376,"PKWT",Database!$U$5:$U$376,"BANDUNG") -> 7 | G17: =SUM(C17:F17) -> 7
A18: 7 | B18: Aceh | C18: =COUNTIFS(Database!$M$5:$M$376,"Direksi",Database!$U$5:$U$376,"ACEH") -> 0 | D18: =COUNTIFS(Database!$M$5:$M$376,"ORGANIK",Database!$U$5:$U$376,"ACEH") -> 0 | E18: =COUNTIFS(Database!$M$5:$M$376,"TETAP",Database!$U$5:$U$376,"ACEH") -> 0 | F18: =COUNTIFS(Database!$M$5:$M$376,"PKWT",Database!$U$5:$U$376,"ACEH") -> 3 | G18: =SUM(C18:F18) -> 3
A19: 8 | B19: Makassar | C19: =COUNTIFS(Database!$M$5:$M$376,"Direksi",Database!$U$5:$U$376,"MAKASSAR") -> 0 | D19: =COUNTIFS(Database!$M$5:$M$376,"ORGANIK",Database!$U$5:$U$376,"MAKASSAR") -> 0 | E19: =COUNTIFS(Database!$M$5:$M$376,"TETAP",Database!$U$5:$U$376,"MAKASSAR") -> 0 | F19: =COUNTIFS(Database!$M$5:$M$376,"PKWT",Database!$U$5:$U$376,"MAKASSAR") -> 6 | G19: =SUM(C19:F19) -> 6
A20: 9 | B20: Klaten | C20: =COUNTIFS(Database!$M$5:$M$376,"Direksi",Database!$U$5:$U$376,"KLATEN") -> 0 | D20: =COUNTIFS(Database!$M$5:$M$376,"ORGANIK",Database!$U$5:$U$376,"KLATEN") -> 0 | E20: =COUNTIFS(Database!$M$5:$M$376,"TETAP",Database!$U$5:$U$376,"KLATEN") -> 0 | F20: =COUNTIFS(Database!$M$5:$M$376,"PKWT",Database!$U$5:$U$376,"KLATEN") -> 39 | G20: =SUM(C20:F20) -> 39
A21: 10 | B21: Jakarta | C21: =COUNTIFS(Database!$M$5:$M$376,"Direksi",Database!$U$5:$U$376,"JAKARTA") -> 0 | D21: =COUNTIFS(Database!$M$5:$M$376,"ORGANIK",Database!$U$5:$U$376,"JAKARTA") -> 0 | E21: =COUNTIFS(Database!$M$5:$M$376,"TETAP",Database!$U$5:$U$376,"JAKARTA") -> 0 | F21: =COUNTIFS(Database!$M$5:$M$376,"PKWT",Database!$U$5:$U$376,"JAKARTA") -> 89 | G21: =SUM(C21:F21) -> 89
A22: 11 | B22: Palembang | C22: =COUNTIFS(Database!$M$5:$M$376,"Direksi",Database!$U$5:$U$376,"PALEMBANG") -> 0 | D22: =COUNTIFS(Database!$M$5:$M$376,"ORGANIK",Database!$U$5:$U$376,"PALEMBANG") -> 0 | E22: =COUNTIFS(Database!$M$5:$M$376,"TETAP",Database!$U$5:$U$376,"PALEMBANG") -> 0 | F22: =COUNTIFS(Database!$M$5:$M$376,"PKWT",Database!$U$5:$U$376,"PALEMBANG") -> 32 | G22: =SUM(C22:F22) -> 32
A23: 12 | B23: Padang | C23: =COUNTIFS(Database!$M$5:$M$376,"Direksi",Database!$U$5:$U$376,"PADANG") -> 0 | D23: =COUNTIFS(Database!$M$5:$M$376,"ORGANIK",Database!$U$5:$U$376,"PADANG") -> 0 | E23: =COUNTIFS(Database!$M$5:$M$376,"TETAP",Database!$U$5:$U$376,"PADANG") -> 0 | F23: =COUNTIFS(Database!$M$5:$M$376,"PKWT",Database!$U$5:$U$376,"PADANG") -> 0 | G23: =SUM(C23:F23) -> 0
A24: 13 | B24: Solo | C24: =COUNTIFS(Database!$M$5:$M$376,"Direksi",Database!$U$5:$U$376,"SOLO") -> 0 | D24: =COUNTIFS(Database!$M$5:$M$376,"ORGANIK",Database!$U$5:$U$376,"SOLO") -> 0 | E24: =COUNTIFS(Database!$M$5:$M$376,"TETAP",Database!$U$5:$U$376,"SOLO") -> 0 | F24: =COUNTIFS(Database!$M$5:$M$376,"PKWT",Database!$U$5:$U$376,"SOLO") -> 2 | G24: =SUM(C24:F24) -> 2
A25: 14 | B25: Purwodadi | C25: =COUNTIFS(Database!$M$5:$M$376,"Direksi",Database!$U$5:$U$376,"PURWODADI") -> 0 | D25: =COUNTIFS(Database!$M$5:$M$376,"ORGANIK",Database!$U$5:$U$376,"PURWODADI") -> 0 | E25: =COUNTIFS(Database!$M$5:$M$376,"TETAP",Database!$U$5:$U$376,"PURWODADI") -> 0 | F25: =COUNTIFS(Database!$M$5:$M$376,"PKWT",Database!$U$5:$U$376,"PURWODADI") -> 5 | G25: =SUM(C25:F25) -> 5
A26: 15 | B26: Lampung | C26: =COUNTIFS(Database!$M$5:$M$376,"Direksi",Database!$U$5:$U$376,"LAMPUNG") -> 0 | D26: =COUNTIFS(Database!$M$5:$M$376,"ORGANIK",Database!$U$5:$U$376,"LAMPUNG") -> 0 | E26: =COUNTIFS(Database!$M$5:$M$376,"TETAP",Database!$U$5:$U$376,"LAMPUNG") -> 0 | F26: =COUNTIFS(Database!$M$5:$M$376,"PKWT",Database!$U$5:$U$376,"LAMPUNG") -> 3 | G26: =SUM(C26:F26) -> 3
A27: 16 | B27: Medan | C27: =COUNTIFS(Database!$M$5:$M$376,"Direksi",Database!$U$5:$U$376,"MEDAN") -> 0 | D27: =COUNTIFS(Database!$M$5:$M$376,"ORGANIK",Database!$U$5:$U$376,"MEDAN") -> 0 | E27: =COUNTIFS(Database!$M$5:$M$376,"TETAP",Database!$U$5:$U$376,"MEDAN") -> 0 | F27: =COUNTIFS(Database!$M$5:$M$376,"PKWT",Database!$U$5:$U$376,"MEDAN") -> 2 | G27: =SUM(C27:F27) -> 2
A28: 17 | B28: Surabaya | C28: =COUNTIFS(Database!$M$5:$M$376,"Direksi",Database!$U$5:$U$376,"SURABAYA") -> 0 | D28: =COUNTIFS(Database!$M$5:$M$376,"ORGANIK",Database!$U$5:$U$376,"SURABAYA") -> 0 | E28: =COUNTIFS(Database!$M$5:$M$376,"TETAP",Database!$U$5:$U$376,"SURABAYA") -> 0 | F28: =COUNTIFS(Database!$M$5:$M$376,"PKWT",Database!$U$5:$U$376,"SURABAYA") -> 5 | G28: =SUM(C28:F28) -> 5
A29: 18 | B29: Banyuwangi | C29: =COUNTIFS(Database!$M$5:$M$376,"Direksi",Database!$U$5:$U$376,"BANYUWANGI") -> 0 | D29: =COUNTIFS(Database!$M$5:$M$376,"ORGANIK",Database!$U$5:$U$376,"BANYUWANGI") -> 0 | E29: =COUNTIFS(Database!$M$5:$M$376,"TETAP",Database!$U$5:$U$376,"BANYUWANGI") -> 0 | F29: =COUNTIFS(Database!$M$5:$M$376,"PKWT",Database!$U$5:$U$376,"BANYUWANGI") -> 4 | G29: =SUM(C29:F29) -> 4
A30: 19 | B30: Yogyakarta | C30: =COUNTIFS(Database!$M$5:$M$376,"Direksi",Database!$U$5:$U$376,"yogyakarta") -> 0 | D30: =COUNTIFS(Database!$M$5:$M$376,"ORGANIK",Database!$U$5:$U$376,"yogyakarta") -> 0 | E30: =COUNTIFS(Database!$M$5:$M$376,"TETAP",Database!$U$5:$U$376,"yogyakarta") -> 0 | F30: =COUNTIFS(Database!$M$5:$M$376,"PKWT",Database!$U$5:$U$376,"yogyakarta") -> 9 | G30: =SUM(C30:F30) -> 9
A31: TOTAL | C31: =SUM(C12:C30) -> 0 | D31: =SUM(D12:D30) -> 0 | E31: =SUM(E12:E30) -> 0 | F31: =SUM(F12:F30) -> 296 | G31: =SUM(G12:G30) -> 296
A34: No | B34: Proyek | C34: Golongan | F34: Jumlah
C35: Organik INKA | D35: IMSS Tetap | E35: PKWT
A36: 1 | B36: 5R | C36: =COUNTIFS(Database!$M$5:$M$376,"ORGANIK",Database!$W$5:$W$376,"5R") -> 0 | D36: =COUNTIFS(Database!$M$5:$M$376,"TETAP",Database!$W$5:$W$376,"5R") -> 0 | E36: =COUNTIFS(Database!$M$5:$M$376,"PKWT",Database!$W$5:$W$376,"5R") -> 0 | F36: =SUM(C36:E36) -> 0
A37: 2 | B37: AC | C37: =COUNTIFS(Database!$M$5:$M$376,"ORGANIK",Database!$W$5:$W$376,"AC") -> 0 | D37: =COUNTIFS(Database!$M$5:$M$376,"TETAP",Database!$W$5:$W$376,"AC") -> 0 | E37: =COUNTIFS(Database!$M$5:$M$376,"PKWT",Database!$W$5:$W$376,"AC") -> 0 | F37: =SUM(C37:E37) -> 0
A38: 3 | B38: Aftersales 612 Jogja | C38: =COUNTIFS(Database!$M$5:$M$376,"ORGANIK",Database!$W$5:$W$376,"Aftersales 612 Jogja") -> 0 | D38: =COUNTIFS(Database!$M$5:$M$376,"TETAP",Database!$W$5:$W$376,"Aftersales 612 Jogja") -> 0 | E38: =COUNTIFS(Database!$M$5:$M$376,"PKWT",Database!$W$5:$W$376,"Aftersales 612 Jogja") -> 0 | F38: =SUM(C38:E38) -> 0
A39: 4 | B39: Aftersales 612 Malang | C39: =COUNTIFS(Database!$M$5:$M$376,"ORGANIK",Database!$W$5:$W$376,"Aftersales 612 Malang") -> 0 | D39: =COUNTIFS(Database!$M$5:$M$376,"TETAP",Database!$W$5:$W$376,"Aftersales 612 Malang") -> 0 | E39: =COUNTIFS(Database!$M$5:$M$376,"PKWT",Database!$W$5:$W$376,"Aftersales 612 Malang") -> 0 | F39: =SUM(C39:E39) -> 0
A40: 5 | B40: Aftersales 612 Solo | C40: =COUNTIFS(Database!$M$5:$M$376,"ORGANIK",Database!$W$5:$W$376,"Aftersales 612 Solo") -> 0 | D40: =COUNTIFS(Database!$M$5:$M$376,"TETAP",Database!$W$5:$W$376,"Aftersales 612 Solo") -> 0 | E40: =COUNTIFS(Database!$M$5:$M$376,"PKWT",Database!$W$5:$W$376,"Aftersales 612 Solo") -> 0 | F40: =SUM(C40:E40) -> 0
A41: 6 | B41: Aftersales 612 Surabaya | C41: =COUNTIFS(Database!$M$5:$M$376,"ORGANIK",Database!$W$5:$W$376,"Aftersales 612 Surabaya") -> 0 | D41: =COUNTIFS(Database!$M$5:$M$376,"TETAP",Database!$W$5:$W$376,"Aftersales 612 Surabaya") -> 0 | E41: =COUNTIFS(Database!$M$5:$M$376,"PKWT",Database!$W$5:$W$376,"Aftersales 612 Surabaya") -> 0 | F41: =SUM(C41:E41) -> 0
A42: 7 | B42: Aftersales GGW TEL | C42: =COUNTIFS(Database!$M$5:$M$376,"ORGANIK",Database!$W$5:$W$376,"Aftersales GGW TEL") -> 0 | D42: =COUNTIFS(Database!$M$5:$M$376,"TETAP",Database!$W$5:$W$376,"Aftersales GGW TEL") -> 0 | E42: =COUNTIFS(Database!$M$5:$M$376,"PKWT",Database!$W$5:$W$376,"Aftersales GGW TEL") -> 1 | F42: =SUM(C42:E42) -> 1
A43: 8 | B43: Aftersales KRDE Makassar-Parepare | C43: =COUNTIFS(Database!$M$5:$M$376,"ORGANIK",Database!$W$5:$W$376,"Aftersales KRDE Makassar-Parepare") -> 0 | D43: =COUNTIFS(Database!$M$5:$M$376,"TETAP",Database!$W$5:$W$376,"Aftersales KRDE Makassar-Parepare") -> 0 | E43: =COUNTIFS(Database!$M$5:$M$376,"PKWT",Database!$W$5:$W$376,"Aftersales KRDE Makassar-Parepare") -> 0 | F43: =SUM(C43:E43) -> 0
A44: 9 | B44: Akuntansi | C44: =COUNTIFS(Database!$M$5:$M$376,"ORGANIK",Database!$W$5:$W$376,"Akuntansi") -> 0 | D44: =COUNTIFS(Database!$M$5:$M$376,"TETAP",Database!$W$5:$W$376,"Akuntansi") -> 0 | E44: =COUNTIFS(Database!$M$5:$M$376,"PKWT",Database!$W$5:$W$376,"Akuntansi") -> 1 | F44: =SUM(C44:E44) -> 1
A45: 10 | B45: Banyuwangi | C45: =COUNTIFS(Database!$M$5:$M$376,"ORGANIK",Database!$W$5:$W$376,"Banyuwangi") -> 0 | D45: =COUNTIFS(Database!$M$5:$M$376,"TETAP",Database!$W$5:$W$376,"Banyuwangi") -> 0 | E45: =COUNTIFS(Database!$M$5:$M$376,"PKWT",Database!$W$5:$W$376,"Banyuwangi") -> 0 | F45: =SUM(C45:E45) -> 0
...

Sheet demografi
A2: JENIS KELAMIN
A3: NO | B3: JENIS KELAMIN | C3: JUMLAH
A4: 1 | B4: LAKI LAKI | C4: =COUNTIF(Database!AB4:AB439,"Laki-laki") -> 401 | D4: =C4/C6*100% -> 0.92183908
A5: 2 | B5: PEREMPUAN | C5: =COUNTIF(Database!AB5:AB439,"Perempuan") -> 34 | D5: =C5/C6*100% -> 0.07816092
A6: TOTAL | C6: =SUM(C4:C5) -> 435
A9: PERNIKAHAN
A10: NO | B10: JENIS KELAMIN | C10: JUMLAH | E10: UPDATE
A11: 1 | B11: BELUM KAWIN | C11: =COUNTIFS(Database!AN5:AN382,"BELUM MENIKAH") -> 186 | D11: =C11/$C$14*100% -> 0.49206349 | E11: =COUNTIF(Database!$AN$5:$AN$439,"BELUM MENIKAH") -> 230 | H11: BELUM KAWIN | I11: ( | J11: 196 | K11: ) | L11: 0.49620253
A12: 2 | B12: KAWIN | C12: =COUNTIFS(Database!AN5:AN382,"MENIKAH") -> 188 | D12: =C12/$C$14*100% -> 0.4973545 | E12: =COUNTIF(Database!$AN$5:$AN$439,"MENIKAH") -> 200 | H12: KAWIN | I12: ( | J12: 194 | K12: ) | L12: 0.49113924
A13: 3 | B13: CERAI | C13: =COUNTIFS(Database!AN5:AN382,"CERAI") -> 4 | D13: =C13/$C$14*100% -> 0.010582011 | E13: =COUNTIF(Database!AN7:AN440,"CERAI") -> 5 | H13: CERAI | I13: ( | J13: 5 | K13: ) | L13: 0.012658228
A14: TOTAL | C14: =SUM(C11:C13) -> 378 | E14: =E11+E12+E13 -> 435
A16: Berdasarkan Jumlah Karyawan
A17: No | B17: Penempatan | C17: Golongan | G17: Jumlah
C18: Direksi | D18: Organik INKA | E18: IMSS Tetap | F18: PKWT
A19: 1 | B19: Kantor Salak | C19: =COUNTIFS(Database!$N$5:$N$439,"Direksi",Database!$V$5:$V$439,"IMSS") -> 0 | D19: =COUNTIFS(Database!$N$5:$N$439,"ORGANIK",Database!$V$5:$V$439,"IMSS") -> 0 | E19: =COUNTIFS(Database!$N$5:$N$439,"TETAP",Database!$V$5:$V$439,"IMSS") -> 0 | F19: =COUNTIFS(Database!$N$5:$N$439,"PKWT",Database!$V$5:$V$439,"IMSS") -> 0 | G19: =SUM(C19:F19) -> 0
A20: 2 | B20: GUDANG | C20: =COUNTIFS(Database!$N$5:$N$439,"Direksi",Database!$V$5:$V$439,"GUDANG") -> 0 | D20: =COUNTIFS(Database!$N$5:$N$439,"ORGANIK",Database!$V$5:$V$439,"GUDANG") -> 0 | E20: =COUNTIFS(Database!$N$5:$N$439,"TETAP",Database!$V$5:$V$439,"GUDANG") -> 0 | F20: =COUNTIFS(Database!$N$5:$N$439,"PKWT",Database!$V$5:$V$439,"GUDANG") -> 0 | G20: =SUM(C20:F20) -> 0
A21: 3 | B21: INKA | C21: =COUNTIFS(Database!$N$5:$N$439,"Direksi",Database!$V$5:$V$439,"INKA") -> 0 | D21: =COUNTIFS(Database!$N$5:$N$439,"ORGANIK",Database!$V$5:$V$439,"INKA") -> 0 | E21: =COUNTIFS(Database!$N$5:$N$439,"TETAP",Database!$V$5:$V$439,"INKA") -> 0 | F21: =COUNTIFS(Database!$N$5:$N$439,"PKWT",Database!$V$5:$V$439,"INKA") -> 0 | G21: =SUM(C21:F21) -> 0
A22: 5 | B22: PMU | C22: =COUNTIFS(Database!$N$5:$N$439,"Direksi",Database!$V$5:$V$439,"PMU") -> 0 | D22: =COUNTIFS(Database!$N$5:$N$439,"ORGANIK",Database!$V$5:$V$439,"PMU") -> 0 | E22: =COUNTIFS(Database!$N$5:$N$439,"TETAP",Database!$V$5:$V$439,"PMU") -> 0 | F22: =COUNTIFS(Database!$N$5:$N$439,"PKWT",Database!$V$5:$V$439,"PMU") -> 0 | G22: =SUM(C22:F22) -> 0
A23: 6 | B23: Bandung | C23: =COUNTIFS(Database!$N$5:$N$439,"Direksi",Database!$V$5:$V$439,"BANDUNG") -> 0 | D23: =COUNTIFS(Database!$N$5:$N$439,"ORGANIK",Database!$V$5:$V$439,"BANDUNG") -> 0 | E23: =COUNTIFS(Database!$N$5:$N$439,"TETAP",Database!$V$5:$V$439,"BANDUNG") -> 0 | F23: =COUNTIFS(Database!$N$5:$N$439,"PKWT",Database!$V$5:$V$439,"BANDUNG") -> 0 | G23: =SUM(C23:F23) -> 0
A24: 7 | B24: Aceh | C24: =COUNTIFS(Database!$N$5:$N$439,"Direksi",Database!$V$5:$V$439,"ACEH") -> 0 | D24: =COUNTIFS(Database!$N$5:$N$439,"ORGANIK",Database!$V$5:$V$439,"ACEH") -> 0 | E24: =COUNTIFS(Database!$N$5:$N$439,"TETAP",Database!$V$5:$V$439,"ACEH") -> 0 | F24: =COUNTIFS(Database!$N$5:$N$439,"PKWT",Database!$V$5:$V$439,"ACEH") -> 0 | G24: =SUM(C24:F24) -> 0
A25: 8 | B25: Makassar | C25: =COUNTIFS(Database!$N$5:$N$439,"Direksi",Database!$V$5:$V$439,"MAKASSAR") -> 0 | D25: =COUNTIFS(Database!$N$5:$N$439,"ORGANIK",Database!$V$5:$V$439,"MAKASSAR") -> 0 | E25: =COUNTIFS(Database!$N$5:$N$439,"TETAP",Database!$V$5:$V$439,"MAKASSAR") -> 0 | F25: =COUNTIFS(Database!$N$5:$N$439,"PKWT",Database!$V$5:$V$439,"MAKASSAR") -> 0 | G25: =SUM(C25:F25) -> 0
A26: 9 | B26: Klaten | C26: =COUNTIFS(Database!$N$5:$N$439,"Direksi",Database!$V$5:$V$439,"KLATEN") -> 0 | D26: =COUNTIFS(Database!$N$5:$N$439,"ORGANIK",Database!$V$5:$V$439,"KLATEN") -> 0 | E26: =COUNTIFS(Database!$N$5:$N$439,"TETAP",Database!$V$5:$V$439,"KLATEN") -> 0 | F26: =COUNTIFS(Database!$N$5:$N$439,"PKWT",Database!$V$5:$V$439,"KLATEN") -> 0 | G26: =SUM(C26:F26) -> 0
A27: 10 | B27: Jakarta | C27: =COUNTIFS(Database!$N$5:$N$439,"Direksi",Database!$V$5:$V$439,"JAKARTA") -> 0 | D27: =COUNTIFS(Database!$N$5:$N$439,"ORGANIK",Database!$V$5:$V$439,"JAKARTA") -> 0 | E27: =COUNTIFS(Database!$N$5:$N$439,"TETAP",Database!$V$5:$V$439,"JAKARTA") -> 0 | F27: =COUNTIFS(Database!$N$5:$N$439,"PKWT",Database!$V$5:$V$439,"JAKARTA") -> 0 | G27: =SUM(C27:F27) -> 0
A28: 11 | B28: Palembang | C28: =COUNTIFS(Database!$N$5:$N$439,"Direksi",Database!$V$5:$V$439,"PALEMBANG") -> 0 | D28: =COUNTIFS(Database!$N$5:$N$439,"ORGANIK",Database!$V$5:$V$439,"PALEMBANG") -> 0 | E28: =COUNTIFS(Database!$N$5:$N$439,"TETAP",Database!$V$5:$V$439,"PALEMBANG") -> 0 | F28: =COUNTIFS(Database!$N$5:$N$439,"PKWT",Database!$V$5:$V$439,"PALEMBANG") -> 0 | G28: =SUM(C28:F28) -> 0
A29: 12 | B29: Padang | C29: =COUNTIFS(Database!$N$5:$N$439,"Direksi",Database!$V$5:$V$439,"PADANG") -> 0 | D29: =COUNTIFS(Database!$N$5:$N$439,"ORGANIK",Database!$V$5:$V$439,"PADANG") -> 0 | E29: =COUNTIFS(Database!$N$5:$N$439,"TETAP",Database!$V$5:$V$439,"PADANG") -> 0 | F29: =COUNTIFS(Database!$N$5:$N$439,"PKWT",Database!$V$5:$V$439,"PADANG") -> 0 | G29: =SUM(C29:F29) -> 0
A30: 13 | B30: Solo | C30: =COUNTIFS(Database!$N$5:$N$439,"Direksi",Database!$V$5:$V$439,"SOLO") -> 0 | D30: =COUNTIFS(Database!$N$5:$N$439,"ORGANIK",Database!$V$5:$V$439,"SOLO") -> 0 | E30: =COUNTIFS(Database!$N$5:$N$439,"TETAP",Database!$V$5:$V$439,"SOLO") -> 0 | F30: =COUNTIFS(Database!$N$5:$N$439,"PKWT",Database!$V$5:$V$439,"SOLO") -> 0 | G30: =SUM(C30:F30) -> 0
A31: 14 | B31: Purwodadi | C31: =COUNTIFS(Database!$N$5:$N$439,"Direksi",Database!$V$5:$V$439,"PURWODADI") -> 0 | D31: =COUNTIFS(Database!$N$5:$N$439,"ORGANIK",Database!$V$5:$V$439,"PURWODADI") -> 0 | E31: =COUNTIFS(Database!$N$5:$N$439,"TETAP",Database!$V$5:$V$439,"PURWODADI") -> 0 | F31: =COUNTIFS(Database!$N$5:$N$439,"PKWT",Database!$V$5:$V$439,"PURWODADI") -> 0 | G31: =SUM(C31:F31) -> 0
A32: 15 | B32: Lampung | C32: =COUNTIFS(Database!$N$5:$N$439,"Direksi",Database!$V$5:$V$439,"LAMPUNG") -> 0 | D32: =COUNTIFS(Database!$N$5:$N$439,"ORGANIK",Database!$V$5:$V$439,"LAMPUNG") -> 0 | E32: =COUNTIFS(Database!$N$5:$N$439,"TETAP",Database!$V$5:$V$439,"LAMPUNG") -> 0 | F32: =COUNTIFS(Database!$N$5:$N$439,"PKWT",Database!$V$5:$V$439,"LAMPUNG") -> 0 | G32: =SUM(C32:F32) -> 0
A33: 16 | B33: Medan | C33: =COUNTIFS(Database!$N$5:$N$439,"Direksi",Database!$V$5:$V$439,"MEDAN") -> 0 | D33: =COUNTIFS(Database!$N$5:$N$439,"ORGANIK",Database!$V$5:$V$439,"MEDAN") -> 0 | E33: =COUNTIFS(Database!$N$5:$N$439,"TETAP",Database!$V$5:$V$439,"MEDAN") -> 0 | F33: =COUNTIFS(Database!$N$5:$N$439,"PKWT",Database!$V$5:$V$439,"MEDAN") -> 0 | G33: =SUM(C33:F33) -> 0
A34: 17 | B34: Surabaya | C34: =COUNTIFS(Database!$N$5:$N$439,"Direksi",Database!$V$5:$V$439,"SURABAYA") -> 0 | D34: =COUNTIFS(Database!$N$5:$N$439,"ORGANIK",Database!$V$5:$V$439,"SURABAYA") -> 0 | E34: =COUNTIFS(Database!$N$5:$N$439,"TETAP",Database!$V$5:$V$439,"SURABAYA") -> 0 | F34: =COUNTIFS(Database!$N$5:$N$439,"PKWT",Database!$V$5:$V$439,"SURABAYA") -> 0 | G34: =SUM(C34:F34) -> 0
A35: 18 | B35: Banyuwangi | C35: =COUNTIFS(Database!$N$5:$N$439,"Direksi",Database!$V$5:$V$439,"BANYUWANGI") -> 0 | D35: =COUNTIFS(Database!$N$5:$N$439,"ORGANIK",Database!$V$5:$V$439,"BANYUWANGI") -> 0 | E35: =COUNTIFS(Database!$N$5:$N$439,"TETAP",Database!$V$5:$V$439,"BANYUWANGI") -> 0 | F35: =COUNTIFS(Database!$N$5:$N$439,"PKWT",Database!$V$5:$V$439,"BANYUWANGI") -> 0 | G35: =SUM(C35:F35) -> 0
A36: 19 | B36: Yogyakarta | C36: =COUNTIFS(Database!$N$5:$N$439,"Direksi",Database!$V$5:$V$439,"yogyakarta") -> 0 | D36: =COUNTIFS(Database!$N$5:$N$439,"ORGANIK",Database!$V$5:$V$439,"yogyakarta") -> 0 | E36: =COUNTIFS(Database!$N$5:$N$439,"TETAP",Database!$V$5:$V$439,"yogyakarta") -> 0 | F36: =COUNTIFS(Database!$N$5:$N$439,"PKWT",Database!$V$5:$V$439,"yogyakarta") -> 0 | G36: =SUM(C36:F36) -> 0
A37: TOTAL | C37: =SUM(C19:C36) -> 0 | D37: =SUM(D19:D36) -> 0 | E37: =SUM(E19:E36) -> 0 | F37: =SUM(F19:F36) -> 0 | G37: =SUM(G19:G36) -> 0
A40: No | B40: Proyek | C40: Golongan | F40: Jumlah
C41: Organik INKA | D41: IMSS Tetap | E41: PKWT
A42: 1 | B42: 5R | C42: =COUNTIFS(Database!$N$5:$N$439,"ORGANIK",Database!$X$5:$X$439,"5R") -> 0 | D42: =COUNTIFS(Database!$N$5:$N$439,"TETAP",Database!$X$5:$X$439,"5R") -> 0 | E42: =COUNTIFS(Database!$N$5:$N$439,"PKWT",Database!$X$5:$X$439,"5R") -> 0 | F42: =SUM(C42:E42) -> 0
A43: 2 | B43: AC | C43: =COUNTIFS(Database!$N$5:$N$439,"ORGANIK",Database!$X$5:$X$439,"AC") -> 0 | D43: =COUNTIFS(Database!$N$5:$N$439,"TETAP",Database!$X$5:$X$439,"AC") -> 0 | E43: =COUNTIFS(Database!$N$5:$N$439,"PKWT",Database!$X$5:$X$439,"AC") -> 0 | F43: =SUM(C43:E43) -> 0
A44: 3 | B44: Aftersales 612 Jogja | C44: =COUNTIFS(Database!$N$5:$N$439,"ORGANIK",Database!$X$5:$X$439,"Aftersales 612 Jogja") -> 0 | D44: =COUNTIFS(Database!$N$5:$N$439,"TETAP",Database!$X$5:$X$439,"Aftersales 612 Jogja") -> 0 | E44: =COUNTIFS(Database!$N$5:$N$439,"PKWT",Database!$X$5:$X$439,"Aftersales 612 Jogja") -> 0 | F44: =SUM(C44:E44) -> 0
A45: 4 | B45: Aftersales 612 Malang | C45: =COUNTIFS(Database!$N$5:$N$439,"ORGANIK",Database!$X$5:$X$439,"Aftersales 612 Malang") -> 0 | D45: =COUNTIFS(Database!$N$5:$N$439,"TETAP",Database!$X$5:$X$439,"Aftersales 612 Malang") -> 0 | E45: =COUNTIFS(Database!$N$5:$N$439,"PKWT",Database!$X$5:$X$439,"Aftersales 612 Malang") -> 0 | F45: =SUM(C45:E45) -> 0
A46: 5 | B46: Aftersales 612 Solo | C46: =COUNTIFS(Database!$N$5:$N$439,"ORGANIK",Database!$X$5:$X$439,"Aftersales 612 Solo") -> 0 | D46: =COUNTIFS(Database!$N$5:$N$439,"TETAP",Database!$X$5:$X$439,"Aftersales 612 Solo") -> 0 | E46: =COUNTIFS(Database!$N$5:$N$439,"PKWT",Database!$X$5:$X$439,"Aftersales 612 Solo") -> 0 | F46: =SUM(C46:E46) -> 0
...

Sheet Sheet1
A1: No | B1: KH hari | C1: Nama | D1: NIP Aktif | E1: Rekening Mandiri | F1: Rekening BSI | G1: Rekrutmen | H1: Domisili | I1: Tgl Masuk/ Mutasi | J1: Masa Kerja (Tahun) | K1: Masa Kerja (Bulan) | L1: Status Pegawai | M1: Karyawan | N1: SK Pengangkatan/ Mutasi/ No Kontrak | O1: Tgl. Pengangkatan/ Akhir Kontrak | P1: Jabatan INKA | Q1: Jabatan IMSS | R1: Column2 | S1: Administrasi/ Teknisi | T1: Kota/Lokasi Kerja | U1: Bagian / Proyek | V1: Departemen / Sub Proyek | W1: Divisi | X1: Direktorat | Y1: Sertifikat | Z1: Surat Peringatan Terakhir | AA1: Jenis Kelamin | AB1: Tempat Lahir | AC1: Tgl Lahir | AD1: Usia | AE1: No. KTP | AF1: Alamat | AG1: No. HP | AH1: No Whatsapp | AI1: No Linkaja | AJ1: Email | AK1: BPJS Kes | AL1: BPJS TK | AM1: Status Pernikahan | AN1: Suami/Istri | AO1: Anak 1 | AP1: Anak 2 | AQ1: Anak 3 | AR1: Tambahan | AS1: Ayah Kandung | AT1: Ibu Kandung | AU1: Ayah Mertua | AV1: Ibu Mertua | AW1: Jumlah Tanggungan | AX1: Status Pajak | AY1: Column1 | AZ1: NPWP | BA1: Agama | BB1: Pend Diakui | BC1: Jurusan | BD1: Almamater | BE1: Tahun Lulus | BF1: Pend. Terakhir | BG1: Jurusan Terakhir | BH1: Almamater Terakhir | BI1: Tahun Lulus2 | BJ1: MPP | BK1: Pensiun | BL1: Ukuran Baju (Huruf) | BM1: Ukuran Celana (Huruf) | BN1: Ukuran Sepatu (Angka) | BO1: Vaksin I | BP1: Vaksin II | BQ1: Vaksin III | BR1: No Kontrak | BS1: Awal | BT1: Akhir | BU1: PB I | BV1: No Kontrak2 | BW1: Awal2 | BX1: Akhir2 | BY1: PB II | BZ1: No Kontrak3 | CA1: Awal3 | CB1: Akhir3 | CC1: PB III | CD1: Column3
A2: 370 | B2: #NUM! | C2: REZA KRISTI OKTAVIA | D2: 642402188 | E2: 1710002115122 | G2: Madiun | H2: Madiun | I2: 45323 | J2: 0 | K2: 11 | L2: PKWT | M2: IMSS | O2: 45657 | Q2: Staff | R2: STAF | S2: Administrasi | T2: IMSS | U2: Keuangan | V2: Keuangan | W2: Keuangan | X2: Keuangan SDM dan Manajemen Risiko | AA2: Perempuan | AB2: Madiun | AC2: 35730 | AD2: 27 | AE2: 351909671097000 5 | AF2: Ds. Sambirejo RT. 015 RW. 006, Kec. Jiwan, Kab. Madiun | AG2: 0896 3247 8213 | AH2: 0896 3247 8213 | AJ2: rezakristy51@gmail.com | AK2: 0002085834104 | AL2: 16044462691 | AM2: Menikah | AN2: AUDIT FEBRIANANDA YULIA | AT2: SUMINAH | AW2: 0 | AX2: K/0 | AZ2: 63.474.922.0-621.000 | BA2: Islam | BB2: S1 | BC2: Akuntansi | BD2: Universitas PGRI Madiun | BE2: 2023 | BF2: S1 | BG2: Akuntansi | BH2: Universitas PGRI Madiun | BI2: 2023 | BL2: 16 | BM2: 34 | BN2: 37
A3: 368 | B3: #NUM! | C3: VIKI DIDIK PRASETYO | D3: 642401204 | E3: 1710010882663 | G3: Madiun | H3: Magetan | I3: 45292 | J3: 1 | K3: 0 | L3: PKWT | M3: IMSS | O3: 45657 | Q3: Staff | R3: STAF | S3: Teknisi | T3: INKA | U3: INKA | V3: Pemeliharaan Fasilitas Listrik | W3: Pengelolaan dan Pengendalian Aset INKA | X3: Operasi | AA3: Laki-Laki | AB3: Magetan | AC3: 37217 | AD3: 23 | AE3: 352004271101000 1 | AF3: Banaran 018/003 Kel Kerik Kec Takeran Kab Magetan | AG3: 62 898-6395-026 | AJ3: Masp2211@gmail.com | AK3: 0000738923951 | AL3: 22023994100 | AM3: Belum Menikah | AS3: SUWARNO | AT3: KARMI | AW3: 0 | AX3: TK/0 | BA3: Islam | BB3: SMK | BC3: Teknik Pemesinan | BD3: SMK PSM 2 Takeran Magetan | BE3: 2019 | BF3: SMK | BG3: Teknik Pemesinan | BH3: SMK PSM 2 Takeran Magetan | BI3: 2019 | BL3: L | BM3: L | BN3: 42
A4: 319 | B4: 164 | C4: ZHILAL RATU AQILAH | D4: 642312149 | E4: 1710012742618 | G4: Madiun | H4: Madiun | I4: 45280 | J4: 1 | K4: 0 | L4: PKWT | M4: IMSS | O4: 45838 | Q4: Staff | R4: STAF | S4: Administrasi | T4: IMSS | U4: SDM | V4: SDM dan Umum | W4: SDM dan Umum | X4: Keuangan SDM dan Manajemen Risiko | AA4: Perempuan | AB4: Madiun | AC4: 36670 | AD4: 24 | AE4: 351903640500000 5 | AF4: Desa Kranggan RT 02 RW 01, Kecamatan Geger, Kabupaten Madiun | AG4: +62 82140333953 | AJ4: aqilahratu05@gmail.com | AK4: 0001170755482 | AL4: 24009885153 | AM4: Belum Menikah | AT4: YUENTIE SOVA PUSPIDALIA | AW4: 0 | AX4: TK/0 | AY4: 07.515.215.7-621.000 | AZ4: 07.515.215.7-621.000 | BA4: Islam | BB4: S1 | BC4: Teknik Industri | BD4: Institut Teknologi Sepuluh Nopember | BE4: 2023 | BF4: S1 | BG4: Teknik Industri | BH4: Institut Teknologi Sepuluh Nopember | BI4: 2023
A5: 318 | B5: 164 | C5: VINDY VIRGINE GUCCI | D5: 642312148 | E5: 1710014832201 | G5: Madiun | H5: Madiun | I5: 45280 | J5: 1 | K5: 0 | L5: PKWT | M5: IMSS | O5: 45838 | Q5: Staff | R5: STAF | S5: Administrasi | T5: IMSS | U5: Akuntansi | V5: Akuntansi | W5: Keuangan | X5: Keuangan SDM dan Manajemen Risiko | AA5: Perempuan | AB5: Madiun | AC5: 35318 | AD5: 28 | AE5: 3519025009960003 | AF5: Jl. Adil Makmur No. 05 RT 05 RW 02 Kel. Bangunsari Kec. Dolopo | AG5: +62 87836241340 | AJ5: vindyvirginegucci@gmail.com | AK5: 0000104782408 | AL5: 24036556249 | AM5: Belum Menikah | AW5: 0 | AX5: TK/0 | BA5: Islam | BB5: S1 | BC5: Akuntansi | BD5: Universitas Brawijaya | BE5: 2018 | BF5: S1 | BG5: Akuntansi | BH5: Universitas Brawijaya | BI5: 2018
A6: 317 | B6: 164 | C6: SULTAN ALFIANTSYAH | D6: 642312147 | E6: 1710014832268 | G6: Madiun | H6: Surabaya | I6: 45280 | J6: 1 | K6: 0 | L6: PKWT | M6: IMSS | O6: 45838 | Q6: Staff | R6: STAF | S6: Administrasi | T6: IMSS | U6: Manajemen Risiko | V6: SDM dan Umum | W6: SDM dan Umum | X6: Keuangan SDM dan Manajemen Risiko | AA6: Laki-Laki | AB6: Surabaya | AC6: 36359 | AD6: 25 | AE6: 357810180799000 2 | AF6: Jalan Lebak Timur 3 no. 3-5 | AG6: 6281327154410 | AJ6: sultan.alfiantsyah07@gmail.com | AK6: 0002050159004 | AL6: 24036556264 | AM6: Belum Menikah | AW6: 0 | AX6: TK/0 | AY6: 60.936.649.7-619.000 | AZ6: 60.936.649.7-619.000 | BA6: Islam | BB6: S1 | BC6: Ekonomi | BD6: Universitas Gadjah Mada | BF6: S1 | BG6: Ekonomi | BH6: Universitas Gadjah Mada
A7: 316 | B7: 164 | C7: HANDIKA RIZKI PRATAMA | D7: 642312146 | E7: 1710014832219 | G7: Madiun | H7: Semarang | I7: 45280 | J7: 1 | K7: 0 | L7: PKWT | M7: IMSS | O7: 45838 | Q7: Staff | R7: STAF | S7: Administrasi | T7: IMSS | U7: Engineering | V7: Teknik | W7: Teknik dan Logistik | X7: Operasi | AA7: Laki-Laki | AB7: Semarang | AC7: 36232 | AD7: 25 | AE7: 337402130399000 3 | AF7: Jl. Pergiwati 4 no 26 RT 02 RW 06 Kel. Bulu Lor Kec. Semarang Utara Kota Semarang | AG7: +62 87870742125 | AJ7: handikarizki14@gmail.com | AK7: 0000643453648 | AL7: 24009885104 | AM7: Belum Menikah | AW7: 0 | AX7: TK/0 | BA7: Islam | BB7: S1 | BC7: Teknik Elektro | BD7: Universitas Negeri Semarang | BE7: 2023 | BF7: S1 | BG7: Teknik Elektro | BH7: Universitas Negeri Semarang | BI7: 2023
A8: 315 | B8: 164 | C8: DIMAS DWI KURNIAWAN | D8: 642312144 | E8: 1710014832250 | G8: Madiun | H8: Banyuwangi | I8: 45280 | J8: 1 | K8: 0 | L8: PKWT | M8: IMSS | O8: 45838 | Q8: Staff | R8: STAF | S8: Administrasi | T8: IMSS | U8: Engineering | V8: Teknik | W8: Teknik dan Logistik | X8: Operasi | AA8: Laki-Laki | AB8: Banyuwangi | AC8: 35592 | AD8: 27 | AE8: 351016110697000 1 | AF8: Jalan Brawijaya gg cemara Rt 01 rt 02 Banyuwangi | AG8: +62 813-5394-9238 | AJ8: gencrit11@gmail.com | AK8: 0000115383104 | AL8: 24009885187 | AM8: Belum Menikah | AS8: SURYADI | AT8: ANI SUTRIANI | AW8: 0 | AX8: TK/0 | AY8: 27.386.544.4-627.000 | AZ8: 27.386.544.4-627.000 | BA8: Islam | BB8: S1 | BC8: Teknik Elektro | BD8: Universitas Negeri Malang | BE8: 2023 | BF8: S1 | BG8: Teknik Elektro | BH8: Universitas Negeri Malang | BI8: 2023
A9: 314 | B9: 164 | C9: BIMA AJI KURNIAWAN | D9: 642312143 | E9: 1710014832227 | G9: Madiun | H9: Boyolali | I9: 45280 | J9: 1 | K9: 0 | L9: PKWT | M9: IMSS | O9: 45838 | Q9: Staff | R9: STAF | S9: Administrasi | T9: IMSS | U9: Pemasaran | V9: Pemasaran | W9: Pemasaran | X9: Utama | AA9: Laki-Laki | AB9: Boyolali | AC9: 36947 | AD9: 23 | AE9: 330902250201900 6 | AF9: DK. BULUSARI. RT 004 RW 008. SIDOMULYO AMPEL. BOYOLALI | AG9: 62 87836241340 | AJ9: ajibiima@gmail.com | AK9: 0003174430353 | AL9: 24009885146 | AM9: Belum Menikah | AS9: AGUS SRI RAHARJO | AT9: WIKUNTARI | AW9: 0 | AX9: TK/0 | AY9: 610040891527000 | AZ9: 610040891527000 | BA9: Islam | BB9: S1 | BC9: Manajemen | BD9: Universitas Sebelas Maret Surakarta | BE9: 2022 | BF9: S1 | BG9: Manajemen | BH9: Universitas Sebelas Maret Surakarta | BI9: 2022
A10: 313 | B10: 164 | C10: BAGUS ADIIB AL-HAQ | D10: 642312142 | E10: 1710014832235 | G10: Madiun | H10: Ngawi | I10: 45280 | J10: 1 | K10: 0 | L10: PKWT | M10: IMSS | O10: 45838 | Q10: Staff | R10: STAF | S10: Administrasi | T10: IMSS | U10: Pemasaran | V10: Pemasaran | W10: Pemasaran | X10: Utama | AA10: Laki-Laki | AB10: Ngawi | AC10: 33838 | AD10: 32 | AE10: 352113220892000 3 | AF10: RT 03, RW 07, Desa Sambirejo, Kecamatan Mantingan, Kabupaten Ngawi | AG10: 62 82120167121 | AJ10: alhaqbagus@gmail.com | AK10: 0000106101145 | AL10: 24009885179 | AM10: Belum Menikah | AW10: 0 | AX10: TK/0 | BA10: Islam | BB10: S2 | BC10: Teknik dan Manajemen Industri | BD10: Institut Teknologi Bandung | BE10: 2021 | BF10: S2 | BG10: Teknik dan Manajemen Industri | BH10: Institut Teknologi Bandung | BI10: 2021
A11: 312 | B11: 164 | C11: ARIEF DWI KURNIAWAN | D11: 642312141 | E11: 1710014832193 | G11: Madiun | H11: Ponorogo | I11: 45280 | J11: 1 | K11: 0 | L11: PKWT | M11: IMSS | O11: 45838 | Q11: Staff | R11: STAF | S11: Administrasi | T11: IMSS | U11: IT | V11: Teknik | W11: Teknik dan Logistik | X11: Operasi | AA11: Laki-Laki | AB11: Ponorogo | AC11: 35539 | AD11: 27 | AE11: 350217190497000 3 | AF11: JL. TRUNOJOYO 38 RT. 005 RW. 001, KEL. MANGKUJAYAN, KEC. PONOROGO, KAB. PONOROGO | AG11: +62 857-3677-5858 | AJ11: ariefkurniawan.it@gmail.com | AK11: 0001283413408 | AL11: 24009885120 | AM11: Belum Menikah | AW11: 0 | AX11: TK/0 | BA11: Islam | BB11: S1 | BC11: Sistem Informasi | BD11: Universitas Brawijaya | BE11: 2021 | BF11: S1 | BG11: Sistem Informasi | BH11: Universitas Brawijaya | BI11: 2021
A12: 311 | B12: 164 | C12: ALVIN DEVOTE AZARIA ARDANA | D12: 642312140 | E12: 1710014832276 | G12: Madiun | H12: Klaten | I12: 45280 | J12: 1 | K12: 0 | L12: PKWT | M12: IMSS | O12: 45838 | Q12: Staff | R12: STAF | S12: Administrasi | T12: IMSS | U12: Legal | V12: Sekper, Legal dan Tata Kelola | W12: Sekper, Legal dan Tata Kelola | X12: Utama | AA12: Laki-Laki | AB12: Klaten | AC12: 36769 | AD12: 24 | AE12: 331026310800000 1 | AF12: Krapyak RT 001 RW 007 Merbung, Klaten Selatan, Klaten, Jawa Tengah | AG12: +62 812-5210-3030 | AJ12: devote48@gmail.com | AK12: 0001160585662 | AL12: 24009885138 | AM12: Belum Menikah | AS12: ARISTIYANTO S.SOS | AT12: IDA HERAWATI S.E | AW12: 0 | AX12: TK/0 | AY12: 50.359.124.0-525.000 | AZ12: 50.359.124.0-525.000 | BA12: Islam | BB12: S1 | BC12: Hukum | BD12: Universitas Sebelas Maret Surakarta | BE12: 2023 | BF12: S1 | BG12: Hukum | BH12: Universitas Sebelas Maret Surakarta | BI12: 2023
A13: 229 | B13: #NUM! | C13: FRISKA NANDA SUSANTA | D13: 642201126 | E13: 1710007727087 | G13: Madiun | H13: Madiun | I13: 44565 | J13: 3 | K13: 0 | L13: PKWT | M13: IMSS | O13: 45657 | Q13: Staff | R13: STAF | S13: Administrasi | T13: IMSS | U13: Pengelolaan Proyek Wilayah I | V13: Pengelolaan Proyek Wilayah I | W13: Wilayah I | X13: Operasi | AA13: Perempuan | AB13: Madiun | AC13: 36188 | AD13: 25 | AE13: 357702680199000 5 | AF13: Perum Griya Salak Blok D/01 RT 49/RW6 Kel. Taman Kec. Taman Kota Madiun | AG13: 0812 4678 2660 | AJ13: friska22nanda@gmail.com | AK13: 0000976562807 | AL13: 22017333562 | AM13: Belum Menikah | AW13: 0 | AX13: TK/0 | BA13: Islam | BB13: D3 | BC13: Manajemen Transportasi Perkeretaapian | BD13: Politeknik Perkeretaapian Indonesia Madiun | BE13: 2020 | BF13: D3 | BG13: Manajemen Transportasi Perkeretaapian | BH13: Politeknik Perkeretaapian Indonesia | BI13: 2020 | BQ13: 44601 | CD13: #N/A
A14: 228 | B14: #NUM! | C14: DITA KAROLIN SABELLA | D14: 642201128 | E14: 1710007727012 | G14: Madiun | H14: Madiun | I14: 44565 | J14: 3 | K14: 0 | L14: PKWT | M14: IMSS | O14: 45657 | Q14: Staff | R14: STAF | S14: Administrasi | T14: IMSS | U14: Umum | V14: SDM dan Umum | W14: SDM dan Umum | X14: Keuangan SDM dan Manajemen Risiko | AA14: Perempuan | AB14: Madiun | AC14: 36297 | AD14: 25 | AE14: 351904570599000 1 | AF14: Mranggen, RT/RW 012/003, Ds Joho, Kec. Dagangan, Kab. Madiun | AG14: 0822 2410 1125 | AJ14: ditakarolin17@gmail.com | AK14: 0001410757817 | AL14: 22017333554 | AM14: Belum Menikah | AW14: 0 | AX14: TK/0 | BA14: Islam | BB14: D3 | BC14: Komputer Akuntansi | BD14: Politeknik Negeri Madiun | BE14: 2021 | BF14: D3 | BG14: Komputer Akuntansi | BH14: Politeknik Negeri Madiun | BI14: 2021 | BQ14: 44601 | CD14: #N/A
A15: 227 | B15: #NUM! | C15: DEVIANA FATKULKHOIR | D15: 642201129 | E15: 1710007726907 | G15: Madiun | H15: Madiun | I15: 44565 | J15: 3 | K15: 0 | L15: PKWT | M15: IMSS | O15: 45657 | Q15: Staff | R15: STAF | S15: Administrasi | T15: IMSS | U15: Sekretariat Perusahaan | V15: Sekper, Legal dan Tata Kelola | W15: Sekper, Legal dan Tata Kelola | X15: Utama | AA15: Perempuan | AB15: Madiun | AC15: 36567 | AD15: 24 | AE15: 351903510200000 1 | AF15: Purworejo RT/RW 023/003 Ds Purworejo, Geger, Kab. Madiun | AG15: 0815 1525 7802 | AJ15: devianafatkulkhoir@gmail.com | AK15: 0000736981648 | AL15: 22017333588 | AM15: Belum Menikah | AW15: 0 | AX15: TK/0 | BA15: Islam | BB15: D3 | BC15: Komputer Akuntansi | BD15: Politeknik Negeri Madiun | BE15: 2021 | BF15: D3 | BG15: Komputer Akuntansi | BH15: Politeknik Negeri Madiun | BI15: 2021 | BQ15: 44950 | CD15: #N/A
A16: 226 | B16: #NUM! | C16: DELA OKTAVIANA | D16: 642201127 | E16: 1710007727160 | G16: Madiun | H16: Madiun | I16: 44565 | J16: 3 | K16: 0 | L16: PKWT | M16: IMSS | O16: 45657 | Q16: Staff | R16: STAF | S16: Administrasi | T16: IMSS | U16: Pemasaran | V16: Pemasaran | W16: Pemasaran | X16: Utama | AA16: Perempuan | AB16: Madiun | AC16: 36447 | AD16: 25 | AE16: 357702541099000 1 | AF16: Perum Bumi Winongo Indah Blok D.05 RT/RW 029/010, Winongo, Manguharjo, Kota Madiun | AG16: 0858 5367 2033 | AJ16: delaoktaviana.do@gmail.com | AK16: 0001276355733 | AL16: 22017333539 | AM16: Belum Menikah | AS16: ERWANTO DJOKO PRIJONO | AT16: JUNA IDAH | AW16: 0 | AX16: TK/0 | AY16: 03.682.871.3.621.000 | AZ16: 036828713621000 | BA16: Islam | BB16: D3 | BC16: Administrasi Bisnis | BD16: Politeknik Negeri Madiun | BE16: 2021 | BF16: D3 | BG16: Administrasi Bisnis | BH16: Politeknik Negeri Madiun | BI16: 2021 | BQ16: 44611 | CD16: #N/A
A17: 210 | B17: #NUM! | C17: BAGAS YAZID GHOZI | D17: 642101093 | E17: 1710005976744 | G17: Madiun | H17: Madiun | I17: 44200 | J17: 4 | K17: 0 | L17: PKWT | M17: IMSS | O17: 45657 | Q17: Staff | R17: STAF | S17: Administrasi | T17: IMSS | U17: IT | V17: Teknik | W17: Teknik dan Logistik | X17: Operasi | AA17: Laki-Laki | AB17: Madiun | AC17: 35302 | AD17: 28 | AE17: 351907250896000 1 | AF17: Ds Wungu RT/RW 005/001, Kec. Wungu, Kab. Madiun | AG17: 0853 4065 3142 | AJ17: bagasyazid7@gmail.com | AK17: 0002907085871 | AL17: 19095813127 | AM17: Menikah | AW17: 0 | AX17: K/0 | AZ17: 86.994.098.2-621.000 | BA17: Islam | BB17: D3 | BC17: Teknik Komputer Kontrol | BD17: Politeknik Negeri Madiun | BE17: 2018 | BF17: D3 | BG17: Teknik Komputer Kontrol | BH17: Politeknik Negeri Madiun | BI17: 2018 | BO17: 44294 | BP17: 44322 | BQ17: 44657 | CD17: #N/A
A18: 209 | B18: #NUM! | C18: SARAH AYU JUNIA KURNIASIH | D18: 642101097 | E18: 1710000713431 | G18: Madiun | H18: Madiun | I18: 44200 | J18: 4 | K18: 0 | L18: PKWT | M18: IMSS | O18: 45657 | Q18: Staff | R18: STAF | S18: Administrasi | T18: INKA | U18: Admin | V18: Pengelolaan dan Pengendalian Aset INKA | W18: Pengelolaan dan Pengendalian Aset INKA | X18: Operasi | AA18: Perempuan | AB18: Madiun | AC18: 34511 | AD18: 30 | AE18: 351903660694000 1 | AF18: Ds Sobrah RT/RW 001/001 Kec. Wungu, Kab, Madiun | AG18: 0838 6709 4057 | AJ18: sayujunea@gmail.com | AK18: 0001281687568 | AL18: 21008126308 | AM18: Menikah | AN18: ERVIN SUNARTO | AW18: 0 | AX18: K/0 | AY18: 03.720.982.2-621.000 | AZ18: 03.720.982.2-621.000 | BA18: Islam | BB18: SMK | BC18: Administrasi Perkantoran | BD18: SMK N 5 Madiun | BF18: S1 | BG18: Manajemen | BH18: Universitas PGRI Madiun | BO18: Promil | BP18: Promil | CD18: #N/A
A19: 191 | B19: #NUM! | C19: RIZKY MAULANA INDROSAPUTRO | D19: 642003087 | E19: 1440009032522 | G19: Madiun | H19: Madiun | I19: 43905 | J19: 4 | K19: 10 | L19: PKWT | M19: IMSS | O19: 45657 | Q19: Staff | R19: STAF | S19: Administrasi | T19: IMSS | U19: Pengelolaan Proyek Wilayah II | V19: Wilayah II | W19: Wilayah II | X19: Operasi | AA19: Laki-Laki | AB19: Surakarta | AC19: 32788 | AD19: 35 | AE19: 357703071089000 1 | AF19: Perum Bumi Mas Blok E No 20 RT/RW 054/012, Mojorejo, Taman, Madiun | AG19: 0812 3038 7261 | AJ19: aquaairminum456@gmail.com | AK19: 0001204479663 | AL19: 20029482799 | AM19: Belum Menikah | AS19: KURNIJANTO INDROTOMO | AT19: WIWIEK WINARTI | AW19: 0 | AX19: TK/0 | AY19: 16.437.677.4-621.000 | AZ19: 16.437.677.4-621.000 | BA19: Islam | BB19: S1 | BC19: Hubungan Internasional | BD19: Universitas Gadjah Mada | BE19: 2016 | BF19: S1 | BG19: Hubungan Internasional | BH19: Universitas Gadjah Mada | BI19: 2016 | BN19: 41 | BO19: 44294 | BP19: 44322 | BQ19: 44672 | CD19: #N/A
A20: 182 | B20: #NUM! | C20: RIAN PRATAMA | D20: 641907279 | E20: 1710005657096 | G20: Madiun | H20: Palembang | I20: 43661 | J20: 5 | K20: 6 | L20: PKWT | M20: IMSS | N20: PKWT-641907279 /D1/2019 | O20: 45487 | Q20: Staff | R20: STAF | S20: Administrasi | T20: IMSS | U20: Pengelolaan Proyek Wilayah II | V20: Wilayah II | W20: Wilayah II | X20: Operasi | AA20: Laki-Laki | AB20: Palembang | AC20: 32244 | AD20: 36 | AE20: 320129110488000 3 | AF20: Jl Urip Sumoharjo Komplek Griya Sekojo No.2991 Blok C4, RT 29 RW 10 Kec. Ilir Timur II Palembang | AG20: 0812 8175 8210 | AJ20: rian.nafisha@gmail.com | AK20: 0001505835707 | AL20: 19063315378 | AM20: Menikah | AN20: MUTASA TIARA | AO20: KHAIRA NAFISHA | AP20: KHANSA NAIFAH | AW20: 2 | AX20: K/2 | BA20: Islam | BB20: S1 | BC20: Teknik Mesin | BD20: Universitas Sriwijaya | BE20: 2011 | BF20: S1 | BG20: Teknik Mesin | BH20: Universitas Sriwijaya | BI20: 2011 | BN20: 42 | BO20: 44293 | BP20: 44322 | BQ20: 44905 | CD20: #N/A
A21: 89 | B21: #NUM! | C21: YOGA BIMANTARA ADITYA WICAKSONO | D21: 642001034 | E21: 1710004040872 | G21: Madiun | H21: Magetan | I21: 42919 | J21: 7 | K21: 6 | L21: PKWT | M21: IMSS | N21: PKWT-642001034 /D1/2020 | O21: 45657 | Q21: Staff | R21: STAF | S21: Administrasi | T21: IMSS | U21: Pengelolaan Proyek Wilayah I | V21: Pengelolaan Proyek Wilayah I | W21: Wilayah I | X21: Operasi | AA21: Laki-Laki | AB21: Salatiga | AC21: 34574 | AD21: 30 | AE21: 352006280994000 2 | AF21: Kpr Pondok Magetan Indah Blok Q No8, Magetan | AG21: 0812 3169 2593 | AJ21: yogabimantaraadityawicaksono@gmail.com | AK21: 0001106495785 | AL21: 17043907868 | AM21: Menikah | AN21: AFIN NURUL ANDINI | AS21: KAHONO | AT21: TIPUK NUR HAYATI | AU21: DARMADI | AV21: JUNANENI | AW21: 0 | AX21: K/0 | AY21: 60.933.776.1-646.000 | AZ21: 60.933.776.1-646.000 | BA21: Islam | BB21: D3 | BC21: Teknik Elektro | BD21: Universitas Gadjah Mada | BE21: 2016 | BF21: D3 | BG21: Teknik Elektro | BH21: Universitas Gadjah Mada | BI21: 2016 | BL21: L | BM21: 38 | BN21: 42 | BO21: 44294 | BP21: 44322 | BQ21: 44601 | CD21: #N/A
A22: 422 | B22: 318 | C22: AHINDA AFRILIA RISTIANINGRUM | D22: 642412239 | G22: Madiun | H22: Madiun | I22: 45628 | J22: 0 | K22: 0 | L22: PKWT | M22: IMSS | O22: 45992 | Q22: Staf / Pelaksana / Teknisi | R22: STAF | S22: Administrasi | T22: IMSS | U22: Staf Ahli Direktur Keuangan, SDM dan Manajemen Risiko | V22: Staf Ahli Direktur Keuangan, SDM dan Manajemen Risiko | W22: SDM dan Umum | X22: Keuangan SDM dan Manajemen Risiko | AA22: Perempuan | AB22: Magetan | AC22: 31160 | AD22: 39 | AE22: 3520046304860001 | AF22: Perum Graha mas Blok A8 Jl Sukarno Hatta | AG22: 081229913641 | AI22: 081229913641 | AJ22: ahindaar@gmail.com | AK22: 0001449448795 | AL22: 20033431022 | AM22: Cerai | AW22: 0 | AX22: TK/0 | BA22: Islam | BB22: S1 | BC22: Pendidikan Olahraga | BD22: IKIP Budi Utomo Malang | BE22: 2010 | BF22: S1 | BG22: Pendidikan Olahraga | BH22: IKIP Budi Utomo Malang | BI22: 2010
A23: 421 | B23: #NUM! | C23: YUSUF ABDULLAH | D23: 642409238 | E23: 1710016324959 | G23: Madiun | H23: Madiun | I23: 45598 | J23: 0 | K23: 0 | L23: PKWT | M23: IMSS | O23: 45657 | Q23: Staf / Pelaksana / Teknisi | R23: STAF | S23: Teknisi | W23: Wilayah I | X23: Operasi | AA23: Laki-Laki | AB23: Madiun | AC23: 36264 | AD23: 25 | AE23: 3519041404990001 | AF23: Desa Banjarsari Wetan Rt.06 Rw.02 Kec. Dagangan Kab. Madiun madiun | AG23: 085854130555 | AH23: +62 858-5413-0555 | AI23: - | AJ23: yusufonline14@gmail.com | AK23: 0000102370735 | AL23: 24192575926 | AM23: Menikah | AN23: LUTFIA INDRIANI | AO23: MUHAMMAD HENOKH AL MASYISY | AS23: KUAT SAROSA (ALM) | AT23: SITI RUKANAH | AU23: BASIR SISWANTO | AV23: KHUSNUL KHOIRIYAH | AW23: 1 | AX23: K/1 | BA23: Islam | BB23: D3 | BC23: Teknologi Bangunan dan Jalur Perkeretaapian | BD23: Politeknik Perkeretaapian Indonesia | BE23: 2020 | BF23: D3 | BG23: Teknologi Bangunan dan Jalur Perkeretaapian | BH23: Politeknik Perkeretaapian Indonesia | BI23: 2020 | BL23: L | BM23: L | BN23: 42
A24: 420 | B24: #NUM! | C24: WARDHANI PUNTO PRABOWO | D24: 642409236 | E24: 1710016324843 | G24: Madiun | H24: Madiun | I24: 45598 | J24: 0 | K24: 0 | L24: PKWT | M24: IMSS | O24: 45657 | Q24: Staf / Pelaksana / Teknisi | R24: STAF | S24: Teknisi | W24: Wilayah I | X24: Operasi | AA24: Laki-Laki | AB24: Madiun | AC24: 37374 | AD24: 22 | AE24: 3577012804020002 | AF24: Jl. Pilang Madya No.29 001/001 Kelurahan Pilangbango Kecamatan Kartoharjo | AG24: 087761402458 | AH24: 087761402458 | AI24: 087761402458 | AJ24: wardhanipunto28@gmail.com | AK24: 0001704811937 | AL24: 24192575892 | AM24: Belum Menikah | AS24: SUWARNO | AT24: ENDANG TRIMURTI | AW24: 0 | AX24: TK/0 | BA24: Islam | BB24: D4 | BC24: Teknik Perkeretaapian | BD24: Politeknik Negeri Madiun | BE24: 2024 | BF24: D4 | BG24: Teknik Perkeretaapian | BH24: Politeknik Negeri Madiun | BI24: 2024 | BL24: XL | BM24: XXL | BN24: 44
A25: 419 | B25: #NUM! | C25: SHONUFIT AR ROYAN F | D25: 642409235 | E25: 1710016324884 | G25: Madiun | H25: Banyuwangi | I25: 45598 | J25: 0 | K25: 0 | L25: PKWT | M25: IMSS | O25: 45657 | Q25: Staf / Pelaksana / Teknisi | R25: STAF | S25: Teknisi | W25: Wilayah I | X25: Operasi | AA25: Laki-Laki | AB25: Banyuwangi | AC25: 37315 | AD25: 22 | AE25: 3510032802020002 | AF25: Dusun Krajan 002/002 Kel Kradenan, Kec Purwoharjo, Kab Banyuwangi, Jawa timur | AG25: 082 141 534 300 | AH25: 082141534300 | AI25: 082141534300 | AJ25: Shonufit@gmail.com | AK25: 0000194802232 | AL25: 24192575942 | AM25: Belum Menikah | AS25: MOH NUR SHOLEH | AT25: NURHAYATI | AW25: 0 | AX25: TK/0 | BA25: Islam | BB25: D3 | BC25: Teknologi Mekanika Perkeretaapian | BD25: Politeknik Perkeretaapian Indonesia Madiun | BE25: 2024 | BF25: D3 | BG25: Teknologi Mekanika Perkeretaapian | BH25: Politeknik Perkeretaapian Indonesia Madiun | BI25: 2024 | BL25: M | BM25: M | BN25: 41
A26: 418 | B26: #NUM! | C26: RISMA ALFIYANI | D26: 642409234 | E26: 1710016324900 | G26: Madiun | H26: Madiun | I26: 45598 | J26: 0 | K26: 0 | L26: PKWT | M26: IMSS | O26: 45657 | Q26: Staf / Pelaksana / Teknisi | R26: STAF | S26: Teknisi | W26: Wilayah I | X26: Operasi | AA26: Perempuan | AB26: Madiun | AC26: 37116 | AD26: 23 | AE26: 3519035308010001 | AF26: Ds. Jatisari RT.08 RW.02, Geger, Madiun | AG26: 082335222595 | AH26: 082335222595 | AI26: 082335222595 | AJ26: rismaalfiyani36@gmail.com | AK26: 0003432923302 | AL26: 24192575884 | AM26: Belum Menikah | AS26: BASYUNI | AT26: RIYANI | AW26: 0 | AX26: TK/0 | BA26: Islam | BB26: D4 | BC26: Teknik Perkeretaapian | BD26: Politeknik Negeri Madiun | BE26: 2023 | BF26: D4 | BG26: Teknik Perkeretaapian | BH26: Politeknik Negeri Madiun | BI26: 2023 | BL26: M | BM26: L | BN26: 39
A27: 380 | B27: #NUM! | C27: SURJONO | D27: 642402194 | G27: Madiun | H27: Madiun | I27: 45413 | J27: 0 | K27: 8 | L27: PKWT | M27: IMSS | O27: 45658 | Q27: Kepala Divisi | R27: BOD - 1 | S27: Administrasi | T27: IMSS | U27: Staf Ahli Direktur Utama | V27: Staf Ahli Direktur Utama | W27: Staf Ahli Direktur Utama | X27: Utama | AA27: Laki-Laki | AB27: Madiun | AC27: 24664 | AD27: 57 | AE27: 3577011107670005 | AF27: Jl. Indra Manis II No 5 027/008 Kel. Manisrejo, Kec Taman Kota Madiun | AG27: +62 812-7809-316 | AJ27: smedhioen@gmail.com | AK27: 0001520765144 | AL27: 24049876485 | AM27: Menikah | AW27: 0 | AX27: K/0 | BA27: Islam | BB27: S1 | BD27: SMA SEDERAJAT | BF27: S1
A28: 417 | B28: #NUM! | C28: OKY NUR FAHREZI | D28: 642409233 | E28: 1710016324934 | G28: Madiun | H28: Madiun | I28: 45598 | J28: 0 | K28: 0 | L28: PKWT | M28: IMSS | O28: 45657 | Q28: Staf / Pelaksana / Teknisi | R28: STAF | S28: Teknisi | W28: Wilayah I | X28: Operasi | AA28: Laki-Laki | AB28: Garut | AC28: 36051 | AD28: 26 | AE28: 3519071309980003 | AF28: Jalan Teratai RT 08/02 Kecamatan Wungu Kabupaten Madiun,63181 | AG28: 083821219792 | AH28: 081333667498 | AI28: 081333667498 | AJ28: okynurfahrezi123@gmail.com | AK28: 0001045283703 | AL28: 24192575868 | AM28: Belum Menikah | AT28: TATIN SUMIATIN | AW28: 0 | AX28: TK/0 | BA28: Islam | BB28: SMK | BC28: Teknik Kendaraan Ringan | BD28: SMK Gamaliel 1 Madiun | BE28: 2016 | BF28: SMK | BG28: Teknik Kendaraan Ringan | BH28: SMK Gamaliel 1 Madiun | BI28: 2016 | BL28: L | BM28: L | BN28: 41
A29: 416 | B29: #NUM! | C29: OCTO AMRI MANSYURIN | D29: 642409232 | E29: 1710016324850 | G29: Madiun | H29: Tangerang | I29: 45598 | J29: 0 | K29: 0 | L29: PKWT | M29: IMSS | O29: 45657 | Q29: Staf / Pelaksana / Teknisi | R29: STAF | S29: Teknisi | W29: Wilayah I | X29: Operasi | AA29: Laki-Laki | AB29: Tangerang | AC29: 37167 | AD29: 23 | AE29: 3603010310010003 | AF29: Villa Balaraja Blok FI/18 RT/RW 04/04 Desa saga Kec Balerejo Kab Tangerang | AG29: 08557255860 | AH29: 08557255860 | AI29: 08557255860 | AJ29: oktoamrim@gmail.com | AK29: 0003103804181 | AL29: 24192575918 | AM29: Belum Menikah | AS29: MUHIDDIN | AT29: SULASRIANI ABDULLAH | AW29: 0 | AX29: TK/0 | AZ29: 022338701451000 | BA29: Islam | BB29: D3 | BC29: Teknologi Mekanika Perkeretaapian | BD29: Politeknik Perkeretaapian Indonesia Madiun | BE29: 2024 | BF29: D3 | BG29: Teknologi Mekanika Perkeretaapian | BH29: Politeknik Perkeretaapian Indonesia Madiun | BI29: 2024 | BL29: L | BM29: L | BN29: 41
A30: 415 | B30: #NUM! | C30: MUHAMMAD TSAMARAH NATIZATUS SULUK | D30: 642409231 | E30: 1710016324892 | G30: Madiun | H30: Madiun | I30: 45598 | J30: 0 | K30: 0 | L30: PKWT | M30: IMSS | O30: 45657 | Q30: Staf / Pelaksana / Teknisi | R30: STAF | S30: Teknisi | W30: Wilayah I | X30: Operasi | AA30: Laki-Laki | AB30: Madiun | AC30: 36998 | AD30: 23 | AE30: 3577031704010002 | AF30: PERUM PANORAMA WILIS B/2 KEL.PANDEAN KEC.TAMAN KOTA MADIUN | AG30: 0895341197500 | AH30: 0895341197500 | AI30: 0895341197500 | AJ30: muhammadiza33@gmail.com | AK30: 0002416864836 | AL30: 24192575975 | AM30: Belum Menikah | AS30: AHMAD LUKMAN | AT30: RACHMA SETYAWATI | AW30: 0 | AX30: TK/0 | AZ30: - | BA30: Islam | BB30: S1 | BC30: Teknik Mesin | BD30: Universitas Muhammadiyah Surakarta | BE30: 2024 | BF30: S1 | BG30: Teknik Mesin | BH30: Universitas Muhammadiyah Surakarta | BI30: 2024 | BL30: XL | BM30: XL | BN30: 43
A31: 414 | B31: #NUM! | C31: MUHAMMAD ABDUL AZIZ | D31: 642409230 | E31: 1710016324868 | G31: Madiun | H31: Magetan | I31: 45598 | J31: 0 | K31: 0 | L31: PKWT | M31: IMSS | O31: 45657 | Q31: Staf / Pelaksana / Teknisi | R31: STAF | S31: Teknisi | W31: Wilayah I | X31: Operasi | AA31: Laki-Laki | AB31: Magetan | AC31: 36632 | AD31: 24 | AE31: 3520101604000001 | AF31: RT 13 RW 02, Desa Dukuh, Kecamatan Bendo, Kabupaten Magetan | AG31: 082232525120 | AH31: 082232525120 | AI31: 082232525120 | AJ31: mabdulaziz0814@gmail.com | AK31: 0000740379554 | AL31: 24192575934 | AM31: Belum Menikah | AS31: SUPARJO | AT31: SURATI | AW31: 0 | AX31: TK/0 | BA31: Islam | BB31: D4 | BC31: Teknik Perkeretaapian | BD31: Politeknik Negeri Madiun | BE31: 2022 | BF31: D4 | BG31: Teknik Perkeretaapian | BH31: Politeknik Negeri Madiun | BI31: 2022 | BL31: M | BM31: M | BN31: 39
A32: 413 | B32: #NUM! | C32: MOH. TAUFIQ MAHENDRA | D32: 642409229 | E32: 1710016324918 | G32: Madiun | H32: Madiun | I32: 45598 | J32: 0 | K32: 0 | L32: PKWT | M32: IMSS | O32: 45657 | Q32: Staf / Pelaksana / Teknisi | R32: STAF | S32: Teknisi | W32: Wilayah I | X32: Operasi | AA32: Laki-Laki | AB32: Madiun | AC32: 37267 | AD32: 23 | AE32: 3577021101020001 | AF32: Jl. Muria No 6, Kel. Pangongangan, Kec. Manguharjo, Kota Madiun | AG32: 081333587017 | AH32: 081333587017 | AI32: 081333587017 | AJ32: mohammadtaufiqmahendra@gmail.com | AK32: 0001886534695 | AL32: 24192575850 | AM32: Belum Menikah | AS32: ABDUL MAJID | AT32: PUDJI ASTUTI | AW32: 0 | AX32: TK/0 | BA32: Islam | BB32: D4 | BC32: Teknik Perkeretaapian | BD32: Politeknik Negeri Madiun | BE32: 2024 | BF32: D4 | BG32: Teknik Perkeretaapian | BH32: Politeknik Negeri Madiun | BI32: 2024 | BL32: XXL | BM32: XXXL | BN32: 45
A33: 412 | B33: #NUM! | C33: MIZANUL ULUM | D33: 642409228 | E33: 1710016337993 | G33: Madiun | H33: Tegal | I33: 45598 | J33: 0 | K33: 0 | L33: PKWT | M33: IMSS | O33: 45657 | Q33: Staf / Pelaksana / Teknisi | R33: STAF | S33: Teknisi | W33: Wilayah I | X33: Operasi | AA33: Laki-Laki | AB33: Tegal | AC33: 37291 | AD33: 22 | AE33: 3328020304020007 | AF33: Traju , Kel Traju, Kec Bumijawa ,kab tegal, Jawa tengah | AG33: 0857 2295 2854 | AH33: 085722952854 | AI33: 085722952854 | AJ33: mizanululum77@gmail.com | AK33: 0003626347241 | AL33: 24192575967 | AM33: Belum Menikah | AS33: FATKHI | AT33: WEAH | AW33: 0 | AX33: TK/0 | BA33: Islam | BB33: D3 | BC33: Teknologi Mekanika Perkeretaapian | BD33: Politeknik Perkeretaapian Indonesia Madiun | BE33: 2024 | BF33: D3 | BG33: Teknologi Mekanika Perkeretaapian | BH33: Politeknik Perkeretaapian Indonesia Madiun | BI33: 2024 | BL33: L | BM33: L | BN33: 45
A34: 411 | B34: #NUM! | C34: FIQQI MUHAMMAD ALFIUZZAQI | D34: 642409227 | E34: 1710016324942 | G34: Madiun | H34: Jombang | I34: 45598 | J34: 0 | K34: 0 | L34: PKWT | M34: IMSS | O34: 45657 | Q34: Staf / Pelaksana / Teknisi | R34: STAF | S34: Teknisi | W34: Wilayah I | X34: Operasi | AA34: Laki-Laki | AB34: Jombang | AC34: 37070 | AD34: 23 | AE34: 3517092806010003 | AF34: Jl. Halmahera VII L-03, Kaliwungu, Jombang | AG34: 0895337665390 | AH34: 0895337665390 | AI34: 0895337665390 | AJ34: alfiuzzaqi@gmail.com | AK34: 0000108745457 | AL34: 24192575876 | AM34: Belum Menikah | AS34: SURAT | AT34: SUNARTI | AW34: 0 | AX34: TK/0 | BA34: Islam | BB34: D4 | BC34: Teknik Perkeretaapian | BD34: Politeknik Negeri Madiun | BE34: 2024 | BF34: D4 | BG34: Teknik Perkeretaapian | BH34: Politeknik Negeri Madiun | BI34: 2024 | BL34: XXL | BM34: XXL | BN34: 42
A35: 410 | B35: #NUM! | C35: FAQIH ABDURROHMAN KUSTI | D35: 642409226 | E35: 1710016337985 | G35: Madiun | H35: Magetan | I35: 45598 | J35: 0 | K35: 0 | L35: PKWT | M35: IMSS | O35: 45657 | Q35: Staf / Pelaksana / Teknisi | R35: STAF | S35: Teknisi | W35: Wilayah I | X35: Operasi | AA35: Laki-Laki | AB35: Magetan | AC35: 37685 | AD35: 21 | AE35: 3520130103030001 | AF35: Dk. Gandri kutu Ds. Kauman Kec. Karangrejo Kab. Magetan | AG35: 081358031270 | AH35: 081358031270 | AI35: 081358031270 | AJ35: faqihdilla17@gmail.com | AK35: 0001544250712 | AL35: 24192575900 | AM35: Belum Menikah | AS35: KUSWANTO | AT35: SITI MARPUNGATUN | AW35: 0 | AX35: TK/0 | BA35: Islam | BB35: SMK | BC35: Teknik Otomotif | BD35: SMK N 2 Jiwan | BE35: 2021 | BF35: SMK | BG35: Teknik Otomotif | BH35: SMK N 2 Jiwan | BI35: 2021 | BL35: XL | BM35: XL | BN35: 43
A36: 409 | B36: #NUM! | C36: ELANG RAIHAN PERMANA | D36: 642409225 | E36: 1710016329230 | G36: Madiun | H36: Madiun | I36: 45598 | J36: 0 | K36: 0 | L36: PKWT | M36: IMSS | O36: 45657 | Q36: Staf / Pelaksana / Teknisi | R36: STAF | S36: Teknisi | W36: Wilayah I | X36: Operasi | AA36: Laki-Laki | AB36: Madiun | AC36: 37105 | AD36: 23 | AE36: 3577030208010001 | AF36: Jl. Serayu Timur Perum Griya Kencana D/18, Kota Madiun | AG36: 0895339159322 | AH36: 0895339159322 | AI36: 0895339159322 | AJ36: raihanelang09@gmail.com | AK36: 0001637226854 | AL36: 24192575983 | AM36: Belum Menikah | AS36: KUKUH ARIS PRASETYO | AT36: ENDANG SRI ELIK NURWAHYUNI | AW36: 0 | AX36: TK/0 | AZ36: - | BA36: Islam | BB36: D4 | BC36: Teknik Perkeretaapian | BD36: Politeknik Negeri Madiun | BE36: 2024 | BF36: D4 | BG36: Teknik Perkeretaapian | BH36: Politeknik Negeri Madiun | BI36: 2024 | BL36: L | BM36: L | BN36: 42
A37: 408 | B37: #NUM! | C37: DIAZ PRATAMA | D37: 642409224 | E37: 1710016324876 | G37: Madiun | H37: Madiun | I37: 45598 | J37: 0 | K37: 0 | L37: PKWT | M37: IMSS | O37: 45657 | Q37: Staf / Pelaksana / Teknisi | R37: STAF | S37: Teknisi | W37: Wilayah I | X37: Operasi | AA37: Laki-Laki | AB37: Madiun | AC37: 36293 | AD37: 25 | AE37: 3312171305990002 | AF37: Jl.Jatinangor, Green Indah Nglames Blok F, Nglames, Kab. Madiun | AG37: 083851380855 | AH37: 83851380855 | AI37: 83851380855 | AJ37: diaazpratama@gmail.com | AK37: 0001205055202 | AL37: 24192575959 | AM37: Belum Menikah | AS37: IRWAN JUWONO | AT37: SUSI HARTINI | AW37: 0 | AX37: TK/0 | BA37: Islam | BB37: D4 | BC37: Teknik Perkeretaapian | BD37: Politeknik Negeri Madiun | BE37: 2022 | BF37: D4 | BG37: Teknik Perkeretaapian | BH37: Politeknik Negeri Madiun | BI37: 2022 | BL37: L | BM37: L | BN37: 42
A38: 407 | B38: #NUM! | C38: AFRIZA KRIDO ANANTA | D38: 642409223 | E38: 1710016324926 | G38: Madiun | H38: Madiun | I38: 45581 | J38: 0 | K38: 0 | L38: PKWT | M38: IMSS | O38: 45657 | Q38: Staf / Pelaksana / Teknisi | R38: STAF | S38: Teknisi | W38: Wilayah II | X38: Operasi | AA38: Laki-Laki | AB38: Madiun | AC38: 38470 | AD38: 19 | AE38: 3519072804050002 | AF38: Kresek Wungu Madiun, Kel Kresek, Kec Wungu, Kab Madiun, Jawa Timur | AG38: +62 857-9065-8921 | AH38: 085790658921 | AI38: 085790658921 | AJ38: afrizaananta6@gmail.com | AK38: 0000737397009 | AL38: 24154903660 | AM38: Belum Menikah | AS38: SLAMET | AT38: DINEM | AW38: 0 | AX38: TK/0 | BA38: Islam | BB38: SMK | BC38: Teknik Instalasi Tenaga Listrik | BD38: SMK Gamaliel 1 Madiun | BE38: 2023 | BF38: SMK | BG38: Teknik Instalasi Tenaga Listrik | BH38: SMK Gamaliel 1 Madiun | BI38: 2023 | BL38: L | BM38: L | BN38: 40
A39: 3 | B39: #NUM! | C39: IRWAN AHMADI | D39: 642001016 | E39: 1710003988097 | G39: Madiun | H39: Madiun | I39: 42005 | J39: 10 | K39: 0 | L39: PKWT | M39: IMSS | O39: 45657 | Q39: Staf / Pelaksana / Teknisi | R39: STAF | S39: Teknisi | T39: INKA | U39: INKA | V39: Perawatan AC | W39: Pengelolaan dan Pengendalian Aset INKA | X39: Operasi | Z39: - | AA39: Laki-Laki | AB39: Madiun | AC39: 33093 | AD39: 34 | AE39: 351914080890000 1 | AF39: Kajang 011/002 Kel. Kajang, Kec.Sawahan, Kab. Madiun | AG39: 0857 0882 7309 | AJ39: ahmadiirwan770@gmail.com | AK39: 0001865422686 | AL39: 16013068701 | AM39: Menikah | AN39: IRWAN AHMADI | AO39: KEVIN ALDAN ALWAFI | AS39: MARDI | AT39: SUPARTUN | AU39: SUPARLAN | AV39: JUMIATUN | AW39: 1 | AX39: K/1 | AY39: 05.517.620.0-621.000 | AZ39: 05.517.620.0-621.000 | BA39: Islam | BB39: SMK | BC39: Teknik Mesin | BD39: MTS N Kota Madiun | BE39: 2007 | BF39: SMP | BG39: Teknik Mesin | BH39: MTS N Kota Madiun | BI39: 2007 | BL39: XL | BM39: 34 | BN39: 42 | BO39: 44308 | BP39: 44336 | BS39: 43467 | BT39: 43830 | BU39: PB-56/XII/IMSS/2019 | BV39: PKWT-971900032/D1/2020 | CD39: #N/A
A40: 4 | B40: #NUM! | C40: AGUS SANTOSO | D40: 642001017 | E40: 1710003988279 | G40: Madiun | H40: Madiun | I40: 42005 | J40: 10 | K40: 0 | L40: PKWT | M40: IMSS | O40: 45657 | Q40: Staf / Pelaksana / Teknisi | R40: STAF | S40: Teknisi | T40: INKA | U40: Fungsional | V40: Wilayah I | W40: Wilayah I | X40: Operasi | Z40: - | AA40: Laki-Laki | AB40: Madiun | AC40: 26892 | AD40: 51 | AE40: 357702160873000 1 | AF40: Jl. Singosari III/12 B RT/RW 013/003 Patihan Manguharjo Madiun | AG40: 0819 3172 9473 | AH40: 0812 9277 8518 | AJ40: Dekecenk@gmail.com | AK40: 0001865423924 | AL40: 16013068669 | AM40: Menikah | AN40: DIAN ARINDA EKANINGTYAS | AO40: QUINSHA AGUSTINA PUTRI | AW40: 1 | AX40: K/1 | BA40: Islam | BB40: SMP | BC40: IPS | BD40: SMA SEDERAJAT | BF40: SMP | BL40: M | BM40: 28 | BN40: 40 | BO40: 44308 | BP40: 44336 | BQ40: 44601 | BS40: 43467 | BT40: 43830 | BU40: PB-55/XII/IMSS/2019 | BV40: PKWT-641807168/D1/2020 | CD40: #N/A
...

Sheet dashboard (EDIT)
A1: Distribusi Pada Status Pegawai | E1: Jenis Kelamin | H1: Kariawan IMSS dan Perbantuan
A2: STATUS PEGAWAI | B2: Jumlah | E2: Jenis Kelamin | F2: Jumlah | H2: Jumlah | I2: Column Labels
A3: PKWT | B3: 344 | E3: Laki-Laki | F3: 392 | H3: Karyawan | I3: Laki-Laki | J3: Perempuan | K3: (blank) | L3: Grand Total
A4: (blank) | E4: Perempuan | F4: 28 | H4: IMSS | I4: 378 | J4: 23 | L4: 401 | R4: Divisi | S4: Sipil | T4: Keuangan | U4: SAR | V4: PPA | W4: PMU | X4: SD, | Y4: LEGAL | Z4: SMK3 | AA4: SPI | AB4: Staf Ahli Direktur Utama | AC4: Teknik dan Logistik | AD4: Wilayah I | AE4: Wilayah II | AF4: Direksi
A5: ORGANIK IMSS | B5: 57 | E5: (blank) | H5: INKA | I5: 14 | J5: 5 | L5: 19 | R5: Jumlah | S5: 6 | T5: 7 | U5: 12 | V5: 52 | W5: 2 | X5: 8 | Y5: 3 | Z5: 2 | AA5: 1 | AB5: 1 | AC5: 26 | AD5: 208 | AE5: 96 | AF5: 3
A6: ORGANIK INKA | B6: 19 | E6: Grand Total | F6: 420 | H6: (blank) | R6: % | S6: 0.014051522 | T6: 0.016393443 | U6: 0.028103044 | V6: 0.12177986 | W6: 0.0046838407 | X6: 0.018735363 | Y6: 0.0070257611 | Z6: 0.0046838407 | AA6: 0.0023419204 | AB6: 0.0023419204 | AC6: 0.06088993 | AD6: 0.48711944 | AE6: 0.22482436 | AF6: 0.0070257611
A7: Grand Total | B7: 420 | H7: Grand Total | I7: 392 | J7: 28 | L7: 420
A8: DISTRIBUSI PEGAWAI PT IMSS PADA TIAP UNIT KERJA | E8: Status Pernikahan | R8: Divisi | S8: Sipil | T8: Keuangan | U8: SAR | V8: PPA | W8: PMU | X8: SD, | Y8: LEGAL | Z8: SMK3 | AA8: SPI | AB8: Staf Ahli Direktur Utama | AC8: Teknik dan Logistik | AD8: Wilayah I | AE8: Wilayah II | AF8: Direksi
A9: Divisi | B9: Jumlah | C9: Count of Divisi | E9: Jumlah | F9: Count of Status Pernikahan | R9: Jumlah | S9: 6 | T9: 7 | U9: 12 | V9: 52 | W9: 2 | X9: 8 | Y9: 3 | Z9: 2 | AA9: 1 | AB9: 1 | AC9: 26 | AD9: 193 | AE9: 96 | AF9: 3
A10: SIPIL | B10: 6 | C10: 0.014285714 | E10: 420 | F10: 420 | R10: % | S10: 0.014563107 | T10: 0.016990291 | U10: 0.029126214 | V10: 0.12621359 | W10: 0.0048543689 | X10: 0.019417476 | Y10: 0.0072815534 | Z10: 0.0048543689 | AA10: 0.0024271845 | AB10: 0.0024271845 | AC10: 0.063106796 | AD10: 0.4684466 | AE10: 0.23300971 | AF10: 0.0072815534
A11: Keuangan | B11: 7 | C11: 0.016666667
A12: SAR | B12: 12 | C12: 0.028571429 | E12: Status Pendidikan | H12: GOLONGAN JABATAN
A13: PPA | B13: 52 | C13: 0.12380952 | E13: Status | F13: Jumlah | H13: Status | I13: Jumlah
A14: PMU | B14: 2 | C14: 0.0047619048 | E14: D2 | F14: 1 | H14: STAF | I14: 394
A15: SDM | B15: 9 | C15: 0.021428571 | E15: D3 | F15: 53 | H15: BOD - 3 | I15: 5
